[2023-06-16 12:15:40,870] {taskinstance.py:1159} INFO - Dependencies all met for <TaskInstance: postgres_dag.createtable_task scheduled__2023-06-15T00:00:00+00:00 [queued]>
[2023-06-16 12:15:40,877] {taskinstance.py:1159} INFO - Dependencies all met for <TaskInstance: postgres_dag.createtable_task scheduled__2023-06-15T00:00:00+00:00 [queued]>
[2023-06-16 12:15:40,878] {taskinstance.py:1356} INFO - 
--------------------------------------------------------------------------------
[2023-06-16 12:15:40,878] {taskinstance.py:1357} INFO - Starting attempt 2 of 2
[2023-06-16 12:15:40,878] {taskinstance.py:1358} INFO - 
--------------------------------------------------------------------------------
[2023-06-16 12:15:40,886] {taskinstance.py:1377} INFO - Executing <Task(PostgresOperator): createtable_task> on 2023-06-15 00:00:00+00:00
[2023-06-16 12:15:40,890] {standard_task_runner.py:52} INFO - Started process 554 to run task
[2023-06-16 12:15:40,893] {standard_task_runner.py:79} INFO - Running: ['***', 'tasks', 'run', 'postgres_dag', 'createtable_task', 'scheduled__2023-06-15T00:00:00+00:00', '--job-id', '4', '--raw', '--subdir', 'DAGS_FOLDER/postgres_dag.py', '--cfg-path', '/tmp/tmpnwayw8z9', '--error-file', '/tmp/tmpa31f5_6f']
[2023-06-16 12:15:40,893] {standard_task_runner.py:80} INFO - Job 4: Subtask createtable_task
[2023-06-16 12:15:40,933] {task_command.py:370} INFO - Running <TaskInstance: postgres_dag.createtable_task scheduled__2023-06-15T00:00:00+00:00 [running]> on host f97be8e8a009
[2023-06-16 12:15:40,977] {taskinstance.py:1571} INFO - Exporting the following env vars:
AIRFLOW_CTX_DAG_OWNER=***
AIRFLOW_CTX_DAG_ID=postgres_dag
AIRFLOW_CTX_TASK_ID=createtable_task
AIRFLOW_CTX_EXECUTION_DATE=2023-06-15T00:00:00+00:00
AIRFLOW_CTX_TRY_NUMBER=2
AIRFLOW_CTX_DAG_RUN_ID=scheduled__2023-06-15T00:00:00+00:00
[2023-06-16 12:15:40,995] {taskinstance.py:1889} ERROR - Task failed with exception
Traceback (most recent call last):
  File "/home/airflow/.local/lib/python3.7/site-packages/airflow/providers/postgres/operators/postgres.py", line 92, in execute
    self.hook.run(self.sql, self.autocommit, parameters=self.parameters)
  File "/home/airflow/.local/lib/python3.7/site-packages/airflow/hooks/dbapi.py", line 186, in run
    with closing(self.get_conn()) as conn:
  File "/home/airflow/.local/lib/python3.7/site-packages/airflow/providers/postgres/hooks/postgres.py", line 86, in get_conn
    conn = deepcopy(self.connection or self.get_connection(conn_id))
  File "/home/airflow/.local/lib/python3.7/site-packages/airflow/hooks/base.py", line 67, in get_connection
    conn = Connection.get_connection_from_secrets(conn_id)
  File "/home/airflow/.local/lib/python3.7/site-packages/airflow/models/connection.py", line 430, in get_connection_from_secrets
    raise AirflowNotFoundException(f"The conn_id `{conn_id}` isn't defined")
airflow.exceptions.AirflowNotFoundException: The conn_id `postgre_assign` isn't defined
[2023-06-16 12:15:40,999] {taskinstance.py:1400} INFO - Marking task as FAILED. dag_id=postgres_dag, task_id=createtable_task, execution_date=20230615T000000, start_date=20230616T121540, end_date=20230616T121540
[2023-06-16 12:15:41,006] {standard_task_runner.py:97} ERROR - Failed to execute job 4 for task createtable_task (The conn_id `postgre_assign` isn't defined; 554)
[2023-06-16 12:15:41,026] {local_task_job.py:156} INFO - Task exited with return code 1
[2023-06-16 12:15:41,075] {local_task_job.py:273} INFO - 0 downstream tasks scheduled from follow-on schedule check
